<robot name="acrobot" xmlns:xacro="http://www.ros.org/wiki/xacro">

    <xacro:property name="JOINT_FRICTION" value="0.05"/>
    <xacro:property name="JOINT_DAMPING" value="0.02"/>
    <xacro:property name="MOTOR_TORQUE" value="0.22"/>
    <xacro:property name="MOTOR_VELOCITY" value="1.8"/>
    <xacro:property name="PI" value="3.1415928"/>

    <xacro:property name="MAXIMUM_ANGLE" value="${11*PI/12}"/>

    <link name="base_link" />

    <link name="leg1">
        <inertial>
            <mass value="460.566e-3"/>
            <origin rpy="0 0 0" xyz="30.8842e-3 0.0259 0.3"/>
            <inertia ixx="3.451e-4" ixy="0.0" ixz="0.0"
                     iyy="2.565e-3" iyz="0.0"
                     izz="2.308e-3"/>
        </inertial>
        <visual name="visual">
            <origin rpy="0 0 0" xyz="0 0 0"/>
            <geometry>
                <mesh filename="package://acrobot_description/meshes/leg1.stl" scale="1 1 1"/>
            </geometry>
            <material name="blue">
                <color rgba="0 0 0.8 1"/>
            </material>
        </visual>
    </link>

    <link name="leg2">
        <inertial>
            <mass value="226.876e-3"/>
            <origin rpy="0 0 0" xyz="-105.604e-3 0 0"/>
            <inertia ixx="2.816e-4" ixy="0" ixz="0"
                     iyy="1.764e-3" iyz="0"
                     izz="1.502e-3"/>
        </inertial>
        <visual name="visual">
            <origin rpy="0 0 0" xyz="0 0 0"/>
            <geometry>
                <mesh filename="package://acrobot_description/meshes/leg2.stl" scale="1 1 1"/>
            </geometry>
            <material name="red">
                <color rgba="0.8 0 0 1"/>
            </material>
        </visual>
    </link>

    <joint name="base_link" type="fixed">
        <parent link="base_link"/>
        <child link="leg1"/>
        <origin rpy="0 ${PI/2} 0" xyz="0 0 0.390"/>
    </joint>

    <joint name="joint" type="revolute">
        <parent link="leg1"/>
        <child link="leg2"/>
        <origin rpy="0 0 0" xyz="0 0 0"/>
        <axis xyz="0 1 0"/>
        <dynamics damping="${JOINT_DAMPING}" friction="${JOINT_FRICTION}" />
        <limit effort="${MOTOR_TORQUE}" lower="-${MAXIMUM_ANGLE}" upper="${MAXIMUM_ANGLE}" velocity="${MOTOR_VELOCITY}"/>
    </joint>

</robot>
