<?xml version="1.0" encoding="utf-8"?>
<!-- =================================================================================== -->
<!-- |    This document was autogenerated by xacro from models/acrobot.xacro           | -->
<!-- |    EDITING THIS FILE BY HAND IS NOT RECOMMENDED                                 | -->
<!-- =================================================================================== -->
<robot name="acrobot">
  <link name="base_link"/>
  <link name="leg1">
    <inertial>
      <mass value="436.312e-3"/>
      <origin rpy="0 0 0" xyz="17.88e-3 0 0"/>
      <inertia ixx="3.33e-4" ixy="0.0" ixz="0.0" iyy="9.34e-4" iyz="0.0" izz="6.98e-4"/>
    </inertial>
    <visual name="visual">
      <origin rpy="0 0 0" xyz="0 0 0"/>
      <geometry>
        <mesh filename="package://acrobot_description/meshes/leg1.stl" scale="1 1 1"/>
      </geometry>
      <material name="blue">
        <color rgba="0 0 0.8 1"/>
      </material>
    </visual>
  </link>
  <link name="leg2">
    <inertial>
      <mass value="194.587e-3"/>
      <origin rpy="0 0 0" xyz="-62.1063e-3 0 0"/>
      <inertia ixx="1.97e-4" ixy="0" ixz="0" iyy="4.75e-4" iyz="0" izz="2.97e-4"/>
    </inertial>
    <visual name="visual">
      <origin rpy="0 0 0" xyz="0 0 0"/>
      <geometry>
        <mesh filename="package://acrobot_description/meshes/leg2.stl" scale="1 1 1"/>
      </geometry>
      <material name="red">
        <color rgba="0.8 0 0 1"/>
      </material>
    </visual>
  </link>
  <link name="leg1_extension">
    <inertial>
      <mass value="48.358e-3"/>
      <origin rpy="0 0 0" xyz="125.562e-3 0 0"/>
      <inertia ixx="2.74e-5" ixy="0" ixz="0" iyy="1.68e-4" iyz="0" izz="1.44e-4"/>
    </inertial>
    <visual name="visual">
      <origin rpy="0 0 0" xyz="0 0 0"/>
      <geometry>
        <mesh filename="package://acrobot_description/meshes/leg_extension.stl" scale="1 1 1"/>
      </geometry>
      <material name="red">
        <color rgba="0.8 0 0 1"/>
      </material>
    </visual>
  </link>
  <joint name="base_link" type="fixed">
    <parent link="base_link"/>
    <child link="leg1"/>
    <origin rpy="0 1.5707964 0" xyz="0 0 0.336"/>
  </joint>
  <joint name="joint" type="revolute">
    <parent link="leg1"/>
    <child link="leg2"/>
    <origin rpy="0 0 0" xyz="0 0 0"/>
    <axis xyz="0 1 0"/>
    <dynamics damping="0.02" friction="0.05"/>
    <limit effort="0.22" lower="-3.078760944" upper="3.078760944" velocity="1.8"/>
  </joint>
  <joint name="joint" type="fixed">
    <parent link="leg1"/>
    <child link="leg1_extension"/>
    <origin rpy="0 0 0" xyz="0 0 167.5e-3"/>
  </joint>
</robot>
